<?xml version="1.0" encoding="utf-8"?>
<!-- =================================================================================== -->
<!-- |    This document was autogenerated by xacro from ur5e_robot.urdf.xacro          | -->
<!-- |    EDITING THIS FILE BY HAND IS NOT RECOMMENDED                                 | -->
<!-- =================================================================================== -->
<robot name="ur5e" xmlns:xacro="http://ros.org/wiki/xacro">
  <link name="base_link">
    <visual>
      <geometry>
        <mesh filename="../meshes/ur5e/visual/base.dae"/>
      </geometry>
      <material name="LightGrey">
        <color rgba="0.7 0.7 0.7 1.0"/>
      </material>
    </visual>
    <collision>
      <geometry>
        <mesh filename="../meshes/ur5e/collision/base.stl" scale="1.0 1.0 1.0"/>
      </geometry>
    </collision>
    <inertial>
      <mass value="4.0"/>
      <origin rpy="0 0 0" xyz="0.0 0.0 0.0"/>
      <inertia ixx="0.00443333156" ixy="0.0" ixz="0.0" iyy="0.00443333156" iyz="0.0" izz="0.0072"/>
    </inertial>
  </link>
  <joint name="shoulder_pan_joint" type="revolute">
    <parent link="base_link"/>
    <child link="shoulder_link"/>
    <origin rpy="0.0 0.0 0.0" xyz="0.0 0.0 0.163"/>
    <axis xyz="0 0 1"/>
    <limit effort="150.0" lower="-6.28318530718" upper="6.28318530718" velocity="3.14"/>
    <dynamics damping="0.0" friction="0.0"/>
  </joint>
  <link name="shoulder_link">
    <visual>
      <geometry>
        <mesh filename="../meshes/ur5e/visual/shoulder.dae"/>
      </geometry>
      <material name="LightGrey">
        <color rgba="0.7 0.7 0.7 1.0"/>
      </material>
    </visual>
    <collision>
      <geometry>
        <mesh filename="../meshes/ur5e/collision/shoulder.stl" scale="1.0 1.0 1.0"/>
      </geometry>
    </collision>
    <inertial>
      <mass value="3.7"/>
      <origin rpy="0 0 0" xyz="0.0 0.0 0.0"/>
      <inertia ixx="0.010267495893" ixy="0.0" ixz="0.0" iyy="0.010267495893" iyz="0.0" izz="0.00666"/>
    </inertial>
  </link>
  <joint name="shoulder_lift_joint" type="revolute">
    <parent link="shoulder_link"/>
    <child link="upper_arm_link"/>
    <origin rpy="0.0 1.57079632679 0.0" xyz="0.0 0.138 0.0"/>
    <axis xyz="0 1 0"/>
    <limit effort="150.0" lower="-6.28318530718" upper="6.28318530718" velocity="3.14"/>
    <dynamics damping="0.0" friction="0.0"/>
  </joint>
  <link name="upper_arm_link">
    <visual>
      <geometry>
        <mesh filename="../meshes/ur5e/visual/upperarm.dae"/>
      </geometry>
      <material name="LightGrey">
        <color rgba="0.7 0.7 0.7 1.0"/>
      </material>
    </visual>
    <collision>
      <geometry>
        <mesh filename="../meshes/ur5e/collision/upperarm.stl" scale="1.0 1.0 1.0"/>
      </geometry>
    </collision>
    <inertial>
      <mass value="8.393"/>
      <origin rpy="0 0 0" xyz="0.0 0.0 0.2125"/>
      <inertia ixx="0.133885781862" ixy="0.0" ixz="0.0" iyy="0.133885781862" iyz="0.0" izz="0.0151074"/>
    </inertial>
  </link>
  <joint name="elbow_joint" type="revolute">
    <parent link="upper_arm_link"/>
    <child link="forearm_link"/>
    <origin rpy="0.0 0.0 0.0" xyz="0.0 -0.131 0.425"/>
    <axis xyz="0 1 0"/>
    <limit effort="150.0" lower="-3.14159265359" upper="3.14159265359" velocity="3.14"/>
    <dynamics damping="0.0" friction="0.0"/>
  </joint>
  <link name="forearm_link">
    <visual>
      <geometry>
        <mesh filename="../meshes/ur5e/visual/forearm.dae"/>
      </geometry>
      <material name="LightGrey">
        <color rgba="0.7 0.7 0.7 1.0"/>
      </material>
    </visual>
    <collision>
      <geometry>
        <mesh filename="../meshes/ur5e/collision/forearm.stl" scale="1.0 1.0 1.0"/>
      </geometry>
    </collision>
    <inertial>
      <mass value="2.275"/>
      <origin rpy="0 0 0" xyz="0.0 0.0 0.196"/>
      <inertia ixx="0.0311796208615" ixy="0.0" ixz="0.0" iyy="0.0311796208615" iyz="0.0" izz="0.004095"/>
    </inertial>
  </link>
  <joint name="wrist_1_joint" type="revolute">
    <parent link="forearm_link"/>
    <child link="wrist_1_link"/>
    <origin rpy="0.0 1.57079632679 0.0" xyz="0.0 0.0 0.392"/>
    <axis xyz="0 1 0"/>
    <limit effort="28.0" lower="-6.28318530718" upper="6.28318530718" velocity="6.28"/>
    <dynamics damping="0.0" friction="0.0"/>
  </joint>
  <link name="wrist_1_link">
    <visual>
      <geometry>
        <mesh filename="../meshes/ur5e/visual/wrist1.dae"/>
      </geometry>
      <material name="LightGrey">
        <color rgba="0.7 0.7 0.7 1.0"/>
      </material>
    </visual>
    <collision>
      <geometry>
        <mesh filename="../meshes/ur5e/collision/wrist1.stl" scale="1.0 1.0 1.0"/>
      </geometry>
    </collision>
    <inertial>
      <mass value="1.219"/>
      <origin rpy="0 0 0" xyz="0.0 0.127 0.0"/>
      <inertia ixx="0.00255989897604" ixy="0.0" ixz="0.0" iyy="0.00255989897604" iyz="0.0" izz="0.0021942"/>
    </inertial>
  </link>
  <joint name="wrist_2_joint" type="revolute">
    <parent link="wrist_1_link"/>
    <child link="wrist_2_link"/>
    <origin rpy="0.0 0.0 0.0" xyz="0.0 0.127 0.0"/>
    <axis xyz="0 0 1"/>
    <limit effort="28.0" lower="-6.28318530718" upper="6.28318530718" velocity="6.28"/>
    <dynamics damping="0.0" friction="0.0"/>
  </joint>
  <link name="wrist_2_link">
    <visual>
      <geometry>
        <mesh filename="../meshes/ur5e/visual/wrist2.dae"/>
      </geometry>
      <material name="LightGrey">
        <color rgba="0.7 0.7 0.7 1.0"/>
      </material>
    </visual>
    <collision>
      <geometry>
        <mesh filename="../meshes/ur5e/collision/wrist2.stl" scale="1.0 1.0 1.0"/>
      </geometry>
    </collision>
    <inertial>
      <mass value="1.219"/>
      <origin rpy="0 0 0" xyz="0.0 0.0 0.1"/>
      <inertia ixx="0.00255989897604" ixy="0.0" ixz="0.0" iyy="0.00255989897604" iyz="0.0" izz="0.0021942"/>
    </inertial>
  </link>
  <joint name="wrist_3_joint" type="revolute">
    <parent link="wrist_2_link"/>
    <child link="wrist_3_link"/>
    <origin rpy="0.0 0.0 0.0" xyz="0.0 0.0 0.1"/>
    <axis xyz="0 1 0"/>
    <limit effort="28.0" lower="-6.28318530718" upper="6.28318530718" velocity="6.28"/>
    <dynamics damping="0.0" friction="0.0"/>
  </joint>
  <link name="wrist_3_link">
    <visual>
      <geometry>
        <mesh filename="../meshes/ur5e/visual/wrist3.dae"/>
      </geometry>
      <material name="LightGrey">
        <color rgba="0.7 0.7 0.7 1.0"/>
      </material>
    </visual>
    <collision>
      <geometry>
        <mesh filename="../meshes/ur5e/collision/wrist3.stl" scale="1.0 1.0 1.0"/>
      </geometry>
    </collision>
    <inertial>
      <mass value="0.1879"/>
      <origin rpy="1.57079632679 0 0" xyz="0.0 0.0771 0.0"/>
      <inertia ixx="9.89041005217e-05" ixy="0.0" ixz="0.0" iyy="9.89041005217e-05" iyz="0.0" izz="0.0001321171875"/>
    </inertial>
  </link>
  <joint name="ee_fixed_joint" type="fixed">
    <parent link="wrist_3_link"/>
    <child link="ee_link"/>
    <origin rpy="0.0 0.0 1.57079632679" xyz="0.0 0.1 0.0"/>
  </joint>
  <link name="ee_link">
    <collision>
      <geometry>
        <box size="0.01 0.01 0.01"/>
      </geometry>
      <origin rpy="0 0 0" xyz="-0.01 0 0"/>
    </collision>
  </link>





<!--     ADDITION OF GRIPPER   -->


  <joint name='robotiq_85_base_joint' type='fixed'>
    <parent link="wrist_3_link"/>
    <child link="robotiq_85_base_link"/>
    <origin rpy="-1.57 0.0 0.0" xyz="0.0 0.1 0.0"/>
    <axis xyz="1 0 0"/>
    <limit effort="100" lower="-1" upper="1" velocity="1000"/>
    <dynamics damping="0.0" friction="0.0"/>
  </joint>
  <link
    name="robotiq_85_base_link">
    <inertial>
      <origin
        xyz="0.00021987 -2.3546E-10 0.030163"
        rpy="0 0 0" />
      <mass
        value="0.30915" />
      <inertia
        ixx="0.00028972"
        ixy="-5.7879E-10"
        ixz="-1.8543E-06"
        iyy="0.00030737"
        iyz="1.682E-12"
        izz="0.00019914" />
    </inertial>
    <visual>
      <origin
        xyz="0 0 0"
        rpy="0 0 0" />
      <geometry>
        <mesh
          filename="package://robotiq_arg85_description/meshes/robotiq_85_base_link_fine.STL" />
      </geometry>
      <material
        name="">
        <color
          rgba="0.1 0.1 0.1 1" />
      </material>
    </visual>
    <collision>
      <origin
        xyz="0 0 0"
        rpy="0 0 0" />
      <geometry>
        <mesh
          filename="package://robotiq_arg85_description/meshes/robotiq_85_base_link_coarse.STL" />
      </geometry>
    </collision>
  </link>
  <link
    name="left_outer_knuckle">
    <inertial>
      <origin
        xyz="0.0178331863169983 3.68915177224286E-11 0.0021442477325704"
        rpy="0 0 0" />
      <mass
        value="0.00684838849434396" />
      <inertia
        ixx="2.66832029033166E-07"
        ixy="1.66142314639824E-15"
        ixz="1.45945633322873E-07"
        iyy="1.3889233257419E-06"
        iyz="2.82951161241588E-15"
        izz="1.26603336914415E-06" />
    </inertial>
    <visual>
      <origin
        xyz="0 0 0"
        rpy="0 0 0" />
      <geometry>
        <mesh
          filename="package://robotiq_arg85_description/meshes/outer_knuckle_fine.STL" />
      </geometry>
      <material
        name="">
        <color
          rgba="0.1 0.1 0.1 1" />
      </material>
    </visual>
    <collision>
      <origin
        xyz="0 0 0"
        rpy="0 0 0" />
      <geometry>
        <mesh
          filename="package://robotiq_arg85_description/meshes/outer_knuckle_coarse.STL" />
      </geometry>
    </collision>
  </link>
  <joint
    name="finger_joint"
    type="revolute">
    <origin
      xyz="0.0306011444260539 0 0.0627920162695395"
      rpy="0 0 0" />
    <parent
      link="robotiq_85_base_link" />
    <child
      link="left_outer_knuckle" />
    <axis
      xyz="0 -1 0" />
    <limit
	  lower="-0.5"
      upper="0.725"
      velocity="2.0"
      effort="1000" />
  </joint>
  <link
    name="left_outer_finger">
    <inertial>
      <origin
        xyz="0.00131451599174296 2.88942057994543E-15 0.0215404163180413"
        rpy="0 0 0" />
      <mass
        value="0.0273093985570947" />
      <inertia
        ixx="8.51629628283022E-06"
        ixy="2.58174336207405E-19"
        ixz="3.83829504344079E-07"
        iyy="6.9133328065108E-06"
        iyz="-7.58589926143789E-19"
        izz="2.25006832221981E-06" />
    </inertial>
    <visual>
      <origin
        xyz="0 0 0"
        rpy="0 0 0" />
      <geometry>
        <mesh
          filename="package://robotiq_arg85_description/meshes/outer_finger_fine.STL" />
      </geometry>
      <material
        name="">
        <color
          rgba="0.1 0.1 0.1 1" />
      </material>
    </visual>
    <collision>
      <origin
        xyz="0 0 0"
        rpy="0 0 0" />
      <geometry>
        <mesh
          filename="package://robotiq_arg85_description/meshes/outer_finger_coarse.STL" />
      </geometry>
    </collision>
  </link>
  <joint
    name="left_outer_finger_joint"
    type="fixed">
    <origin
      xyz="0.0316910442266543 0 -0.00193396375724605"
      rpy="0 0 0" />
    <parent
      link="left_outer_knuckle" />
    <child
      link="left_outer_finger" />
    <axis
      xyz="0 -1 0" />
  </joint>
  <link
    name="left_inner_knuckle">
    <inertial>
      <origin
        xyz="0.017097546626628 -3.93808524389535E-10 0.0224918438201868"
        rpy="0 0 0" />
      <mass
        value="0.0110930853895903" />
      <inertia
        ixx="4.23392770691541E-06"
        ixy="5.748978936968E-15"
        ixz="1.78855677119788E-06"
        iyy="3.96548790524392E-06"
        iyz="1.05464666369669E-14"
        izz="3.24068002883007E-06" />
    </inertial>
    <visual>
      <origin
        xyz="0 0 0"
        rpy="0 0 0" />
      <geometry>
        <mesh
          filename="package://robotiq_arg85_description/meshes/inner_knuckle_fine.STL" />
      </geometry>
      <material
        name="">
        <color
          rgba="0.1 0.1 0.1 1" />
      </material>
    </visual>
    <collision>
      <origin
        xyz="0 0 0"
        rpy="0 0 0" />
      <geometry>
        <mesh
          filename="package://robotiq_arg85_description/meshes/inner_knuckle_coarse.STL" />
      </geometry>
    </collision>
  </link>
  <joint
    name="left_inner_knuckle_joint"
    type="revolute">
    <origin
      xyz="0.0127000000001501 0 0.0693074999999639"
      rpy="0 0 0" />
    <parent
      link="robotiq_85_base_link" />
    <child
      link="left_inner_knuckle" />
    <axis
      xyz="0 -1 0" />
    <limit
      lower="0"
      upper="0.8757"
      velocity="2.0"
      effort="1000" />
    <mimic 
      joint="finger_joint"
      multiplier="1"
      offset="0" />
  </joint>
  <link
    name="left_inner_finger">
    <inertial>
      <origin
        xyz="0.0060275613594574 -6.29183141465421E-15 0.00669925693133241"
        rpy="0 0 0" />
      <mass
        value="0.00724255346165745" />
      <inertia
        ixx="1.47824274053603E-06"
        ixy="-3.94884463570303E-19"
        ixz="-3.45268847648622E-07"
        iyy="1.70064480838395E-06"
        iyz="3.5059838910097E-19"
        izz="4.77151336838364E-07" />
    </inertial>
    <visual>
      <origin
        xyz="0 0 0"
        rpy="0 0 0" />
      <geometry>
        <mesh
          filename="package://robotiq_arg85_description/meshes/inner_finger_fine.STL" />
      </geometry>
      <material
        name="">
        <color
          rgba="0.1 0.1 0.1 1" />
      </material>
    </visual>
    <collision>
      <origin
        xyz="0 0 0"
        rpy="0 0 0" />
      <geometry>
        <mesh
          filename="package://robotiq_arg85_description/meshes/inner_finger_coarse.STL" />
      </geometry>
    </collision>
  </link>
  <joint
    name="left_inner_finger_joint"
    type="revolute">
    <origin
      xyz="0.034585310861294 0 0.0454970193817975"
      rpy="0 0 0" />
    <parent
      link="left_inner_knuckle" />
    <child
      link="left_inner_finger" />
    <axis
      xyz="0 -1 0" />
    <limit
      lower="0"
      upper="0.8757"
      velocity="2.0"
      effort="1000" />
    <mimic 
      joint="finger_joint"
      multiplier="-1"
      offset="0" />
  </joint>
  <link
    name="right_inner_knuckle">
    <inertial>
      <origin
        xyz="0.0168606186773776 3.93808471820465E-10 0.0226699950793434"
        rpy="0 0 0" />
      <mass
        value="0.0110930853895903" />
      <inertia
        ixx="4.27134775939882E-06"
        ixy="-8.53568456728898E-15"
        ixz="1.77774229944246E-06"
        iyy="3.96548790524392E-06"
        iyz="-8.45108024914164E-15"
        izz="3.20325997634666E-06" />
    </inertial>
    <visual>
      <origin
        xyz="0 0 0"
        rpy="0 0 0" />
      <geometry>
        <mesh
          filename="package://robotiq_arg85_description/meshes/inner_knuckle_fine.STL" />
      </geometry>
      <material
        name="">
        <color
          rgba="0.1 0.1 0.1 1" />
      </material>
    </visual>
    <collision>
      <origin
        xyz="0 0 0"
        rpy="0 0 0" />
      <geometry>
        <mesh
          filename="package://robotiq_arg85_description/meshes/inner_knuckle_coarse.STL" />
      </geometry>
    </collision>
  </link>
  <joint
    name="right_inner_knuckle_joint"
    type="revolute">
    <origin
      xyz="-0.0126999999998499 0 0.0693075000000361"
      rpy="0 0 3.14159265358979" />
    <parent
      link="robotiq_85_base_link" />
    <child
      link="right_inner_knuckle" />
    <axis
      xyz="0 1 0" />
    <limit
      lower="-0.8757"
      upper="0"
      velocity="2.0"
      effort="1000" />
    <mimic 
      joint="finger_joint"
      multiplier="-1"
      offset="0" />
  </joint>
  <link
    name="right_inner_finger">
    <inertial>
      <origin
        xyz="0.00602756228812038 -6.47284509480176E-15 0.00669925609578108"
        rpy="0 0 0" />
      <mass
        value="0.00724255346165744" />
      <inertia
        ixx="1.47824283625957E-06"
        ixy="-3.95952064019123E-19"
        ixz="-3.45268708875543E-07"
        iyy="1.70064480838394E-06"
        iyz="3.55286507960029E-19"
        izz="4.77151241114822E-07" />
    </inertial>
    <visual>
      <origin
        xyz="0 0 0"
        rpy="0 0 0" />
      <geometry>
        <mesh
          filename="package://robotiq_arg85_description/meshes/inner_finger_fine.STL" />
      </geometry>
      <material
        name="">
        <color
          rgba="0.1 0.1 0.1 1" />
      </material>
    </visual>
    <collision>
      <origin
        xyz="0 0 0"
        rpy="0 0 0" />
      <geometry>
        <mesh
          filename="package://robotiq_arg85_description/meshes/inner_finger_coarse.STL" />
      </geometry>
    </collision>
  </link>
  <joint
    name="right_inner_finger_joint"
    type="revolute">
    <origin
      xyz="0.0341060475457406 0 0.0458573878541688"
      rpy="0 0 0" />
    <parent
      link="right_inner_knuckle" />
    <child
      link="right_inner_finger" />
    <axis
      xyz="0 1 0" />
    <limit
      lower="-0.8757"
      upper="0"
      velocity="2.0"
      effort="1000" />
    <mimic 
      joint="finger_joint"
      multiplier="1"
      offset="0" />
  </joint>
  <link
    name="right_outer_knuckle">
    <inertial>
      <origin
        xyz="0.0178097074051638 3.60493211424024E-11 0.00233123458346721"
        rpy="0 0 0" />
      <mass
        value="0.00684838849401352" />
      <inertia
        ixx="2.70004361573169E-07"
        ixy="1.59579467624491E-15"
        ixz="1.56396493788199E-07"
        iyy="1.38892332558312E-06"
        iyz="2.82357800318817E-15"
        izz="1.26286103637978E-06" />
    </inertial>
    <visual>
      <origin
        xyz="0 0 0"
        rpy="0 0 0" />
      <geometry>
        <mesh
          filename="package://robotiq_arg85_description/meshes/outer_knuckle_fine.STL" />
      </geometry>
      <material
        name="">
        <color
          rgba="0.1 0.1 0.1 1" />
      </material>
    </visual>
    <collision>
      <origin
        xyz="0 0 0"
        rpy="0 0 0" />
      <geometry>
        <mesh
          filename="package://robotiq_arg85_description/meshes/outer_knuckle_coarse.STL" />
      </geometry>
    </collision>
  </link>
  <joint
    name="right_outer_knuckle_joint"
    type="revolute">
    <origin
      xyz="-0.0306011444258893 0 0.0627920162695395"
      rpy="0 0 3.14159265358979" />
    <parent
      link="robotiq_85_base_link" />
    <child
      link="right_outer_knuckle" />
    <axis
      xyz="0 1 0" />
    <limit
      lower="-0.8757"
      upper="0.5"
      velocity="2.0"
      effort="1000" />
    <mimic 
      joint="finger_joint"
      multiplier="-1"
      offset="0" />
  </joint>
  <link
    name="right_outer_finger">
    <inertial>
      <origin
        xyz="0.00108844269639009 -2.611488350845E-15 0.0215530225245502"
        rpy="0 0 0" />
      <mass
        value="0.0273093985570947" />
      <inertia
        ixx="8.52366028592721E-06"
        ixy="3.41683380899422E-19"
        ixz="3.18003675694284E-07"
        iyy="6.91333280651081E-06"
        iyz="7.37726682706417E-19"
        izz="2.24270431912283E-06" />
    </inertial>
    <visual>
      <origin
        xyz="0 0 0"
        rpy="0 0 0" />
      <geometry>
        <mesh
          filename="package://robotiq_arg85_description/meshes/outer_finger_fine.STL" />
      </geometry>
      <material
        name="">
        <color
          rgba="0.1 0.1 0.1 1" />
      </material>
    </visual>
    <collision>
      <origin
        xyz="0 0 0"
        rpy="0 0 0" />
      <geometry>
        <mesh
          filename="package://robotiq_arg85_description/meshes/outer_finger_coarse.STL" />
      </geometry>
    </collision>
  </link>
  <joint
    name="right_outer_finger_joint"
    type="fixed">
    <origin
      xyz="0.0317095909367246 0 -0.0016013564954687"
      rpy="0 0 0" />
    <parent
      link="right_outer_knuckle" />
    <child
      link="right_outer_finger" />
    <axis
      xyz="0 1 0" />
  </joint>


  <transmission name="shoulder_pan_trans">
    <type>transmission_interface/SimpleTransmission</type>
    <joint name="shoulder_pan_joint">
      <hardwareInterface>hardware_interface/PositionJointInterface</hardwareInterface>
    </joint>
    <actuator name="shoulder_pan_motor">
      <mechanicalReduction>1</mechanicalReduction>
    </actuator>
  </transmission>
  <transmission name="shoulder_lift_trans">
    <type>transmission_interface/SimpleTransmission</type>
    <joint name="shoulder_lift_joint">
      <hardwareInterface>hardware_interface/PositionJointInterface</hardwareInterface>
    </joint>
    <actuator name="shoulder_lift_motor">
      <mechanicalReduction>1</mechanicalReduction>
    </actuator>
  </transmission>
  <transmission name="elbow_trans">
    <type>transmission_interface/SimpleTransmission</type>
    <joint name="elbow_joint">
      <hardwareInterface>hardware_interface/PositionJointInterface</hardwareInterface>
    </joint>
    <actuator name="elbow_motor">
      <mechanicalReduction>1</mechanicalReduction>
    </actuator>
  </transmission>
  <transmission name="wrist_1_trans">
    <type>transmission_interface/SimpleTransmission</type>
    <joint name="wrist_1_joint">
      <hardwareInterface>hardware_interface/PositionJointInterface</hardwareInterface>
    </joint>
    <actuator name="wrist_1_motor">
      <mechanicalReduction>1</mechanicalReduction>
    </actuator>
  </transmission>
  <transmission name="wrist_2_trans">
    <type>transmission_interface/SimpleTransmission</type>
    <joint name="wrist_2_joint">
      <hardwareInterface>hardware_interface/PositionJointInterface</hardwareInterface>
    </joint>
    <actuator name="wrist_2_motor">
      <mechanicalReduction>1</mechanicalReduction>
    </actuator>
  </transmission>
  <transmission name="wrist_3_trans">
    <type>transmission_interface/SimpleTransmission</type>
    <joint name="wrist_3_joint">
      <hardwareInterface>hardware_interface/PositionJointInterface</hardwareInterface>
    </joint>
    <actuator name="wrist_3_motor">
      <mechanicalReduction>1</mechanicalReduction>
    </actuator>
  </transmission>
  <gazebo reference="shoulder_link">
    <selfCollide>true</selfCollide>
  </gazebo>
  <gazebo reference="upper_arm_link">
    <selfCollide>true</selfCollide>
  </gazebo>
  <gazebo reference="forearm_link">
    <selfCollide>true</selfCollide>
  </gazebo>
  <gazebo reference="wrist_1_link">
    <selfCollide>true</selfCollide>
  </gazebo>
  <gazebo reference="wrist_3_link">
    <selfCollide>true</selfCollide>
  </gazebo>
  <gazebo reference="wrist_2_link">
    <selfCollide>true</selfCollide>
  </gazebo>
  <gazebo reference="ee_link">
    <selfCollide>true</selfCollide>
  </gazebo>
  <!-- ROS base_link to UR 'Base' Coordinates transform -->
  <link name="base"/>
  <joint name="base_link-base_fixed_joint" type="fixed">
    <!-- NOTE: this rotation is only needed as long as base_link itself is
                 not corrected wrt the real robot (ie: rotated over 180
                 degrees)
      -->
    <origin rpy="0 0 -3.14159265359" xyz="0 0 0"/>
    <parent link="base_link"/>
    <child link="base"/>
  </joint>
  <!-- Frame coincident with all-zeros TCP on UR controller -->
  <link name="tool0"/>
  <joint name="wrist_3_link-tool0_fixed_joint" type="fixed">
    <origin rpy="-1.57079632679 0 0" xyz="0 0.1 0"/>
    <parent link="wrist_3_link"/>
    <child link="tool0"/>
  </joint>
  <link name="world"/>
  <joint name="world_joint" type="fixed">
    <parent link="world"/>
    <child link="base_link"/>
    <origin rpy="0.0 0.0 0.0" xyz="0.0 0.0 0.0"/>
  </joint>
</robot>
