<?xml version="1.0" encoding="utf-8"?>
<robot xmlns:xacro="http://ros.org/wiki/xacro">

  <xacro:include filename="$(find dianaV1_description)/urdf/Diana.transmission.xacro" />
  <xacro:include filename="$(find dianaV1_description)/urdf/Diana.gazebo.xacro" />


  <xacro:macro name="DianaV1_robot" params="prefix joint_limited
    joint1_limitL:=${-170.0/180.0*pi}  joint1_limitU:=${170.0/180.0*pi}
    joint2_limitL:=${-120.0/180.0*pi}    joint2_limitU:=${70.0/180.0*pi}
    joint3_limitL:=${-170.0/180.0*pi}    joint3_limitU:=${170.0/180.0*pi}
    joint4_limitL:=${-88.0/180.0*pi}    joint4_limitU:=${50.0/180.0*pi}
    joint5_limitL:=${-170.0/180.0*pi}  joint5_limitU:=${170.0/180.0*pi}
    joint6_limitL:=${-170.0/180.0*pi}    joint6_limitU:=${20.0/180.0*pi}
    joint7_limitL:=${-170.0/180.0*pi}    joint7_limitU:=${170.0/180.0*pi}
    transmission_hw_interface:=hardware_interface/PositionJointInterface
    safety_limits:=false safety_pos_margin:=0.15
    safety_k_position:=20 safety_k_velocity:=0.0">

    <!-- Kinematic model -->
    <xacro:property name="d1" value="-0.30000" />
    <xacro:property name="d2" value="0.00000" />
    <xacro:property name="d3" value="-0.45856" />
    <xacro:property name="d4" value="0.00000" />
    <xacro:property name="d5" value="-0.44903" />
    <xacro:property name="d6" value="0.00000" />
    <xacro:property name="d7" value="-0.13140" />

    <xacro:property name="a1" value="0.00000" />
    <xacro:property name="a2" value="0.02982" />
    <xacro:property name="a3" value="-0.02982" />
    <xacro:property name="a4" value="0.06768" />
    <xacro:property name="a5" value="-0.04744" />
    <xacro:property name="a6" value="-0.04639" />
    <xacro:property name="a7" value="-0.08791" />

    <xacro:property name="alpha1" value="${pi}" />
    <xacro:property name="alpha2" value="${-0.5*pi}" />
    <xacro:property name="alpha3" value="${0.5*pi}" />
    <xacro:property name="alpha4" value="${-0.5*pi}" />
    <xacro:property name="alpha5" value="${0.5*pi}" />
    <xacro:property name="alpha6" value="${-0.5*pi}" />
    <xacro:property name="alpha7" value="${0.5*pi}" />

    <xacro:property name="joint_effort" value="50.0" />
    <xacro:property name="joint_vel" value="3.14" />
    <xacro:property name="joint_damp" value="0.0" />
    <xacro:property name="joint_frict" value="0.0" />





    <link name="${prefix}base_link">
      <visual>
        <origin yz="0 0 0" rpy="0 0 0" />
        <geometry>
          <mesh filename="package://dianaV1_description/meshes/base_link.STL" />
        </geometry>
        <material name="LightGrey">
          <color rgba="0.7 0.7 0.7 1" />
        </material>
      </visual>
      <collision>
        <origin xyz="0 0 0" rpy="0 0 0" />
        <geometry>
          <mesh filename="package://dianaV1_description/meshes/base_link.STL" />
        </geometry>
      </collision>
    </link>
    <joint name="${prefix}joint1" type="revolute">
      <origin xyz="0 0 ${-d1}" rpy="${alpha1} 0 0" />
      <parent link="${prefix}base_link" />
      <child link="${prefix}link1" />
      <axis xyz="0 0 1" />
      <limit lower="${joint1_limitL}" upper="${joint1_limitU}" effort="${joint_effort}" velocity="${joint_vel}" />
      <xacro:if value="${safety_limits}">
        <safety_controller soft_lower_limit="${joint1_limitL + safety_pos_margin}" soft_upper_limit="${joint1_limitU - safety_pos_margin}"
          k_position="${safety_k_position}" k_velocity="${safety_k_velocity}"/>
      </xacro:if>
      <dynamics damping="${joint_damp}" friction="${joint_frict}"/>
    </joint>  
    <link name="${prefix}link1">
      <inertial>
        <origin xyz="0.0171 0.0 0.0762" rpy="0 0 0" />
        <mass value="7.057" />
        <inertia
          ixx="0.0"
          ixy="0.0"
          ixz="0.0"
          iyy="0.0"
          iyz="0.0"
          izz="0.023" />
      </inertial>
      <visual>
        <origin xyz="0 0 0" rpy="0 0 0" />
        <geometry>
          <mesh filename="package://dianaV1_description/meshes/link1.STL" />
        </geometry>
        <material name="LightGrey">
          <color rgba="0.7 0.7 0.7 1" />
        </material>
      </visual>
      <collision>
        <origin xyz="0 0 0" rpy="0 0 0" />
        <geometry>
          <mesh filename="package://dianaV1_description/meshes/link1.STL" />
        </geometry>
      </collision>
    </link>
    <joint name="${prefix}joint2" type="revolute">
      <origin xyz="${a2} 0 0" rpy="${alpha2} 0 0" />
      <parent link="${prefix}link1" />
      <child link="${prefix}link2" />
      <axis xyz="0 0 1" />
      <limit lower="${joint2_limitL}" upper="${joint2_limitU}" effort="${joint_effort}" velocity="${joint_vel}" />
      <xacro:if value="${safety_limits}">
        <safety_controller soft_lower_limit="${joint2_limitL + safety_pos_margin}" soft_upper_limit="${joint2_limitU - safety_pos_margin}"
          k_position="${safety_k_position}" k_velocity="${safety_k_velocity}"/>
      </xacro:if>
      <dynamics damping="${joint_damp}" friction="${joint_frict}"/>
    </joint>
    <link name="${prefix}link2">
      <inertial>
        <origin xyz="-0.0147 0.0491 -0.036" rpy="0 0 0" />
        <mass value="3.367" />
        <inertia
          ixx="0.0335"
          ixy="0.0"
          ixz="0.0"
          iyy="0.0161"
          iyz="0.0"
          izz="0.0286" />
      </inertial>
      <visual>
        <origin xyz="0 0 0" rpy="0 0 0" />
        <geometry>
          <mesh filename="package://dianaV1_description/meshes/link2.STL" />
        </geometry>
        <material name="LightGrey">
          <color rgba="0.7 0.7 0.7 1" />
        </material>
      </visual>
      <collision>
        <origin xyz="0 0 0" rpy="0 0 0" />
        <geometry>
          <mesh filename="package://dianaV1_description/meshes/link2.STL" />
        </geometry>
      </collision>
    </link>
    <joint name="${prefix}joint3" type="revolute">
      <origin xyz="${a3} ${-d3} 0" rpy="${alpha3} 0 0" />
      <parent link="${prefix}link2" />
      <child link="${prefix}link3" />
      <axis xyz="0 0 1" />
      <limit lower="${joint3_limitL}" upper="${joint3_limitU}" effort="${joint_effort}" velocity="${joint_vel}" />
      <xacro:if value="${safety_limits}">
        <safety_controller soft_lower_limit="${joint3_limitL + safety_pos_margin}" soft_upper_limit="${joint3_limitU - safety_pos_margin}"
          k_position="${safety_k_position}" k_velocity="${safety_k_velocity}"/>
      </xacro:if>
      <dynamics damping="${joint_damp}" friction="${joint_frict}"/>
    </joint>
    <link name="${prefix}link3">
      <inertial>
        <origin xyz="0.0283 0.0035 0.134" rpy="0 0 0" />
        <mass value="4.949" />
        <inertia
          ixx="0.1981"
          ixy="0.0"
          ixz="0.0"
          iyy="0.2068"
          iyz="0.0"
          izz="0.0207" />
      </inertial>
      <visual>
        <origin xyz="0 0 0" rpy="0 0 0" />
        <geometry>
          <mesh filename="package://dianaV1_description/meshes/link3.STL" />
        </geometry>
        <material name="LightGrey">
          <color rgba="0.7 0.7 0.7 1" />
        </material>
      </visual>
      <collision>
        <origin xyz="0 0 0" rpy="0 0 0" />
        <geometry>
          <mesh filename="package://dianaV1_description/meshes/link3.STL" />
        </geometry>
      </collision>
    </link>
    <joint name="${prefix}joint4" type="revolute">
      <origin xyz="${a4} 0 0" rpy="${alpha4} ${-pi/2.0} 0" />
      <parent link="${prefix}link3" />
      <child link="${prefix}link4" />
      <axis xyz="0 0 1" />
      <limit lower="${joint4_limitL}" upper="${joint4_limitU}" effort="${joint_effort}" velocity="${joint_vel}" />
      <xacro:if value="${safety_limits}">
        <safety_controller soft_lower_limit="${joint4_limitL + safety_pos_margin}" soft_upper_limit="${joint4_limitU - safety_pos_margin}"
          k_position="${safety_k_position}" k_velocity="${safety_k_velocity}"/>
      </xacro:if>
      <dynamics damping="${joint_damp}" friction="${joint_frict}"/>
    </joint>
    <link name="${prefix}link4">
      <inertial>
        <origin xyz="-0.0284 0.0426 -0.0222" rpy="0 0 0" />
        <mass value="2.347" />
        <inertia
          ixx="0.0154"
          ixy="0.0"
          ixz="0.0"
          iyy="0.0"
          iyz="0.0"
          izz="0.0167" />
      </inertial>
      <visual>
        <origin xyz="0 0 0" rpy="0 0 0" />
        <geometry>
          <mesh filename="package://dianaV1_description/meshes/link4.STL" />
        </geometry>
        <material name="LightGrey">
          <color rgba="0.7 0.7 0.7 1" />
        </material>
      </visual>
      <collision>
        <origin xyz="0 0 0" rpy="0 0 0" />
        <geometry>
          <mesh filename="package://dianaV1_description/meshes/link4.STL" />
        </geometry>
      </collision>
    </link>
    <joint name="${prefix}joint5" type="revolute">
      <origin xyz="${a5} ${-d5} 0" rpy="${alpha5} 0 0" />
      <parent link="${prefix}link4" />
      <child link="${prefix}link5" />
      <axis xyz="0 0 1" />
      <limit lower="${joint5_limitL}" upper="${joint5_limitU}" effort="${joint_effort}" velocity="${joint_vel}" />
      <xacro:if value="${safety_limits}">
        <safety_controller soft_lower_limit="${joint5_limitL + safety_pos_margin}" soft_upper_limit="${joint5_limitU - safety_pos_margin}"
          k_position="${safety_k_position}" k_velocity="${safety_k_velocity}"/>
      </xacro:if>
      <dynamics damping="${joint_damp}" friction="${joint_frict}"/>
    </joint>
    <link name="${prefix}link5">
      <inertial>
        <origin xyz="-0.0253 0.0007 0.1455" rpy="0 0 0" />
        <mass value="3.2554" />
        <inertia
          ixx="0.1459"
          ixy="0.0"
          ixz="0.0"
          iyy="0.1481"
          iyz="0.0"
          izz="0.0" />
      </inertial>
      <visual>
        <origin xyz="0 0 0" rpy="0 0 0" />
        <geometry>
          <mesh filename="package://dianaV1_description/meshes/link5.STL" />
        </geometry>
        <material name="LightGrey">
          <color rgba="0.7 0.7 0.7 1" />
        </material>
      </visual>
      <collision>
        <origin xyz="0 0 0" rpy="0 0 0" />
        <geometry>
          <mesh filename="package://dianaV1_description/meshes/link5.STL" />
        </geometry>
      </collision>
    </link>
    <joint name="${prefix}joint6" type="revolute">
      <origin xyz="${a6} 0 0" rpy="${alpha6} 0 0" />
      <parent link="${prefix}link5" />
      <child link="${prefix}link6" />
      <axis xyz="0 0 1" />
      <limit lower="${joint6_limitL}" upper="${joint6_limitU}" effort="${joint_effort}" velocity="${joint_vel}" />
      <xacro:if value="${safety_limits}">
        <safety_controller soft_lower_limit="${joint6_limitL + safety_pos_margin}" soft_upper_limit="${joint6_limitU - safety_pos_margin}"
          k_position="${safety_k_position}" k_velocity="${safety_k_velocity}"/>
      </xacro:if>
      <dynamics damping="${joint_damp}" friction="${joint_frict}"/>
    </joint>
    <link name="${prefix}link6">
      <inertial>
        <origin xyz="-0.0613 0.0202 -0.0143" rpy="0 0 0" />
        <mass value="2.627" />
        <inertia
          ixx="0.0"
          ixy="0.0"
          ixz="0.0"
          iyy="0.0189"
          iyz="0.0"
          izz="0.0207" />
      </inertial>
      <visual>
        <origin xyz="0 0 0" rpy="0 0 0" />
        <geometry>
          <mesh filename="package://dianaV1_description/meshes/link6.STL" />
        </geometry>
        <material name="LightGrey">
          <color rgba="0.7 0.7 0.7 1" />
        </material>
      </visual>
      <collision>
        <origin xyz="0 0 0" rpy="0 0 0" />
        <geometry>
          <mesh filename="package://dianaV1_description/meshes/link6.STL" />
        </geometry>
      </collision>
    </link>
    <joint name="${prefix}joint7" type="revolute">
      <origin xyz="${a7} ${-d7} 0" rpy="${alpha7} 0 0" />
      <parent link="${prefix}link6" />
      <child link="${prefix}link7" />
      <axis xyz="0 0 1" />
      <limit lower="${joint7_limitL}" upper="${joint7_limitU}" effort="${joint_effort}" velocity="${joint_vel}" />
      <xacro:if value="${safety_limits}">
        <safety_controller soft_lower_limit="${joint7_limitL + safety_pos_margin}" soft_upper_limit="${joint7_limitU - safety_pos_margin}"
          k_position="${safety_k_position}" k_velocity="${safety_k_velocity}"/>
      </xacro:if>
      <dynamics damping="${joint_damp}" friction="${joint_frict}"/>
    </joint>
    <link name="${prefix}link7">
      <inertial>
        <origin xyz="0.0 0.0 0.0452" rpy="0 0 0" />
        <mass value="0.77" />
        <inertia
          ixx="0.0"
          ixy="0.0"
          ixz="0.0"
          iyy="0.0"
          iyz="0.0"
          izz="0.0" />
      </inertial>
      <visual>
        <origin xyz="0 0 0" rpy="0 0 0" />
        <geometry>
          <mesh filename="package://dianaV1_description/meshes/link7.STL" />
        </geometry>
        <material name="LightGrey">
          <color rgba="0.7 0.7 0.7 1" />
        </material>
      </visual>
      <collision>
        <origin xyz="0 0 0" rpy="0 0 0" />
        <geometry>
          <mesh filename="package://dianaV1_description/meshes/link7.STL" />
        </geometry>
      </collision>
    </link>

    <xacro:Diana_arm_transmission prefix="${prefix}" hw_interface="${transmission_hw_interface}" />
    <xacro:Diana_arm_gazebo prefix="${prefix}" />

  </xacro:macro>
</robot>
